<?xml version="1.0" ?>
<mujoco model="vbot">
  <compiler angle="radian" meshdir="meshes/" />
  <option cone="elliptic" impratio="100" />
  <default>
    <material specular="0" shininess="0.25"/>
    <default class="vita">
      <geom friction="0.4" margin="0.001" condim="3" />
      <joint axis="0 1 0" damping="0.1" armature="0.0043" frictionloss="0.2" />
      <motor forcerange="-17 17" />
      <default class="R_hip_joint">
        <joint
                    axis="1 0 0"
                    range="-0.73304 0.73304"
                    actuatorfrcrange="-17 17"
                    limited="true"
                />
      </default>
      <default class="L_hip_joint">
        <joint
                    axis="1 0 0"
                    range="-0.73304 0.73304"
                    actuatorfrcrange="-17 17"
                    limited="true"
                />
      </default>
      <default class="F_thigh_joint">
        <joint range="-1.559 3.1298" actuatorfrcrange="-17 17" limited="true" />
      </default>
      <default class="R_thigh_joint">
        <joint
                    range="-0.51181 4.177"
                    actuatorfrcrange="-17 17"
                    limited="true"
                />
      </default>
      <default class="calf_joint">
        <joint
                    range="-2.6387 -0.7854"
                    actuatorfrcrange="-34 34"
                    limited="true"
                    damping="0.1"
                    armature="0.04"
                    frictionloss="0.2"
                />
        <motor forcerange="-34 34" />
      </default>
      <default class="visual">
        <geom type="mesh" contype="0" conaffinity="0" group="2" density="0" />
      </default>
      <default class="collision">
        <geom group="3" rgba="0.752941 0.752941 0.752941 1" />
        <default class="foot">
          <geom size="0.021" quat="0.707107 -0.707107 0 0" pos="0 0 0" />
        </default>
      </default>
    </default>
  </default>
  <asset>
    <mesh name="base_link" file="base_link.STL" />
    <mesh name="FR_hip" file="FR_hip.STL" />
    <mesh name="FR_thigh" file="FR_thigh.STL" />
    <mesh name="FR_calf" file="FR_calf.STL" />
    <mesh name="FR_foot" file="FR_foot.STL" />
    <mesh name="FL_hip" file="FL_hip.STL" />
    <mesh name="FL_thigh" file="FL_thigh.STL" />
    <mesh name="FL_calf" file="FL_calf.STL" />
    <mesh name="FL_foot" file="FL_foot.STL" />
    <mesh name="RR_hip" file="RR_hip.STL" />
    <mesh name="RR_thigh" file="RR_thigh.STL" />
    <mesh name="RR_calf" file="RR_calf.STL" />
    <mesh name="RR_foot" file="RR_foot.STL" />
    <mesh name="RL_hip" file="RL_hip.STL" />
    <mesh name="RL_thigh" file="RL_thigh.STL" />
    <mesh name="RL_calf" file="RL_calf.STL" />
    <mesh name="RL_foot" file="RL_foot.STL" />
    <mesh name="head_yaw" file="head_yaw.STL" />
    <mesh name="head_pitch" file="head_pitch.STL" />
    
    <!-- 目标箭头mesh -->
    <mesh name="arrow_cone" file="cone.stl" scale="0.003 0.003 0.003"/>
    
    <!-- 目标箭头材质 -->
    <material name="target_green" rgba="0 1 0 0.9"/>
  </asset>
  <worldbody>
    <light name="spotlight" mode="targetbodycom" target="base" pos="0 -1 2" cutoff="30"/>
    
    <!-- 目标位置标记：三维箭头 (圆柱+圆锥) -->
    <body name="target_marker" pos="0 0 1.5">
      <joint name="target_x" type="slide" axis="1 0 0" limited="false"/>
      <joint name="target_y" type="slide" axis="0 1 0" limited="false"/>
      <joint name="target_yaw" type="hinge" axis="0 0 1" limited="false"/>
      
      <!-- 箭头杆：圆柱体 -->
      <geom name="arrow_shaft" type="cylinder" size="0.03 0.15" 
            pos="0.15 0 0" quat="0.707107 0 0.707107 0" 
            material="target_green" contype="0" conaffinity="0"/>
      
      <!-- 箭头头：圆锥 -->
      <geom name="arrow_head" type="mesh" mesh="arrow_cone" 
            pos="0.28 -0.3 0.09" quat="0.707107 0 0.707107 0"
            material="target_green" contype="0" conaffinity="0"/>
    </body>
    
    <body name="base" pos="0 0 0.462" childclass="vita">
      <inertial
                pos="0.026103 0.000278 0.024686"
                mass="9.016326"
                fullinertia="0.060632  0.144345 0.125819 -0.000200 -0.033265 -0.000044"
            />
      <freejoint name="joint_fixed_world" />
      <site name="trunk_imu" pos="0 0 0" />
      <geom
                type="mesh"
                class="visual"
                pos="0.17289 0 0.12752"
                rgba="0.498039 0.498039 0.498039 1"
                mesh="head_yaw"
            />
        <geom
                type="mesh"
                class="visual"
                pos="0.17289 0 0.15552"
                rgba="0.75294 0.75294 0.75294 1"
                mesh="head_pitch"
            />
        <geom
                name="collision_head_box"
                class="collision"
                size="0.084602 0.078997 0.041873"
                pos="0.18389 0 0.16552"
                type="box"
                rgba="0.498039 0.498039 0.498039 1"
            />
      <geom
                type="mesh"
                rgba="0.752941 0.752941 0.752941 1"
                mesh="base_link"
                class="visual"
            />
      <geom
                name="collision_middle_box"
                size="0.133329 0.101205 0.068913"
                pos="0 0 0.004583"
                type="box"
                class="collision"
            />
      <geom
                name="collision_front_dangban_box"
                size="0.0058255 0.029011 0.029011"
                pos="0.247938 0 0.006492"
                type="box"
                class="collision"
            />
      <geom
                name="collision_back_dangban_box"
                size="0.0058255 0.029011 0.023818"
                pos="-0.249278 0 0.006492"
                type="box"
                class="collision"
            />
      <geom
                name="collision_low_bar_FL_box"
                size="0.008 0.008 0.0065"
                pos="0.083 0.042 -0.086"
                type="box"
                class="collision"
            />
      <geom
                name="collision_low_bar_FR_box"
                size="0.008 0.008 0.0065"
                pos="0.083 -0.042 -0.086"
                type="box"
                class="collision"
            />
      <geom
                name="collision_low_bar_RL_box"
                size="0.008 0.008 0.0065"
                pos="-0.108 0.042 -0.086"
                type="box"
                class="collision"
            />
      <geom
                name="collision_low_bar_RR_box"
                size="0.008 0.008 0.0065"
                pos="-0.108 -0.042 -0.086"
                type="box"
                class="collision"
            />
      <body name="FR_hip" pos="0.18453 -0.051 0">
        <inertial
                    pos="-0.027882 0.015355 0"
                    quat="-0.137609 0.678417 0.233155 0.682973"
                    mass="0.079643"
                    diaginertia="8.72171e-05 7.7874e-05 2.29089e-05"
                />
        <joint name="FR_hip_joint" class="R_hip_joint" />
        <geom
                    type="mesh"
                    rgba="0.898039 0.917647 0.929412 1"
                    mesh="FR_hip"
                    class="visual"
                />
        <body name="FR_thigh" pos="0 -0.0975 0">
          <inertial
                        pos="-0.000498 0.038065 -0.024467"
                        quat="0.975282 -0.219111 0.024734 0.0142991"
                        mass="1.55038"
                        diaginertia="0.00679074 0.00586921 0.00204705"
                    />
          <joint name="FR_thigh_joint" class="F_thigh_joint" />
          <geom
                        type="mesh"
                        rgba="0.498039 0.498039 0.498039 1"
                        mesh="FR_thigh"
                        class="visual"
                    />
          <geom
                        name="collision_mainlink_box"
                        size="0.0129095 0.013 0.06282"
                        pos="-0.029488 -0.000724 -0.10287"
                        quat="0.999071 0 -0.0430946 0"
                        type="box"
                        class="collision"
                    />
          <geom
                        name="collision_self_check_box"
                        size="0.00126 0.013 0.0627725"
                        pos="0.01289 -0.000372 -0.102949"
                        quat="0.997989 0 0.063395 0"
                        type="box"
                        class="collision"
                    />
          <geom
                        name="collision_motor_cylinder"
                        size="0.044 0.038455"
                        pos="0 0.02351 -0.000177"
                        quat="-0.707107 0.707107 0 0"
                        type="cylinder"
                        class="collision"
                    />
          <geom
                        name="collision_revo_left_box"
                        size="0.015 0.002 0.02"
                        pos="-0.00614 0.014268 -0.188644"
                        quat="0.995396 0 -0.0958456 0"
                        type="box"
                        class="collision"
                    />
          <geom
                        name="collision_revo_right_box"
                        size="0.015 0.002 0.02"
                        pos="-0.00614 -0.014448 -0.188644"
                        quat="0.995396 0 -0.0958456 0"
                        type="box"
                        class="collision"
                    />
          <body name="FR_calf" pos="0 0 -0.1985">
            <inertial
                            pos="0.00261631 0 -0.125302"
                            quat="0.706944 -0.0151852 -0.0151852 0.706944"
                            mass="0.183986"
                            diaginertia="0.00125035 0.0012368 3.55485e-05"
                        />
            <joint name="FR_calf_joint" class="calf_joint" />
            <geom
                            type="mesh"
                            rgba="0.498039 0.498039 0.498039 1"
                            mesh="FR_calf"
                            class="visual"
                        />
            <geom
                            name="collision_upper_box"
                            size="0.012 0.007644 0.0242675"
                            pos="0.018049 0 -0.186508"
                            quat="0.998889 0 0.047125 0"
                            type="box"
                            class="collision"
                        />
            <geom
                            size="0.01 0.009 0.06"
                            pos="0.00376 0 -0.099894"
                            quat="0.994686 0 -0.102956 0"
                            type="box"
                            class="collision"
                        />
            <geom
                            name="collision_lower_box"
                            size="0.014 0.007644 0.02"
                            pos="-0.005451 0 -0.017378"
                            quat="0.999978 0 0.00661145 0"
                            type="box"
                            class="collision"
                        />
            <geom
                            name="collision_backprotect_box"
                            size="0.002 0.007644 0.02"
                            pos="-0.001309 0 -0.175631"
                            quat="0.981769 0 0.19008 0"
                            type="box"
                            class="collision"
                        />
            <geom
                            pos="0 0 -0.214"
                            quat="1 0 0 0"
                            type="mesh"
                            rgba="0.498039 0.498039 0.498039 1"
                            mesh="FR_foot"
                            class="visual"
                        />
            <body name="FR_foot" pos="0 0 -0.214">
              <geom class="foot" name="FR" />
            </body>
          </body>
        </body>
      </body>
      <body name="FL_hip" pos="0.18453 0.051 0">
        <inertial
                    pos="-0.027882 -0.015355 0"
                    quat="0.137609 0.678417 -0.233155 0.682973"
                    mass="0.079643"
                    diaginertia="8.72171e-05 7.7874e-05 2.29089e-05"
                />
        <joint name="FL_hip_joint" class="L_hip_joint" />
        <geom type="mesh" rgba="1 1 1 1" mesh="FL_hip" class="visual" />
        <body name="FL_thigh" pos="0 0.0975 0">
          <inertial
                        pos="-0.000498 -0.038065 -0.024467"
                        quat="0.975282 0.219111 0.024734 -0.0142991"
                        mass="1.55038"
                        diaginertia="0.00679074 0.00586921 0.00204705"
                    />
          <joint name="FL_thigh_joint" class="F_thigh_joint" />
          <geom
                        type="mesh"
                        rgba="0.498039 0.498039 0.498039 1"
                        mesh="FL_thigh"
                        class="visual"
                    />
          <geom
                        size="0.0129095 0.013 0.06282"
                        pos="-0.029488 0.000724 -0.10287"
                        quat="0.999071 0 -0.0430946 0"
                        type="box"
                        class="collision"
                    />
          <geom
                        size="0.00126 0.013 0.0627725"
                        pos="0.01289 0.000372 -0.102949"
                        quat="0.997989 0 0.063395 0"
                        type="box"
                        class="collision"
                    />
          <geom
                        size="0.044 0.038455"
                        pos="0 -0.02351 -0.000177"
                        quat="-0.707107 0.707107 0 0"
                        type="cylinder"
                        class="collision"
                    />
          <geom
                        size="0.015 0.002 0.02"
                        pos="-0.00614 -0.014268 -0.188644"
                        quat="0.995396 0 -0.0958456 0"
                        type="box"
                        class="collision"
                    />
          <geom
                        size="0.015 0.002 0.02"
                        pos="-0.00614 0.014448 -0.188644"
                        quat="0.995396 0 -0.0958456 0"
                        type="box"
                        class="collision"
                    />
          <body name="FL_calf" pos="0 0 -0.1985">
            <inertial
                            pos="0.00261631 0 -0.125302"
                            quat="0.706944 -0.0151852 -0.0151852 0.706944"
                            mass="0.183986"
                            diaginertia="0.00125035 0.0012368 3.55485e-05"
                        />
            <joint name="FL_calf_joint" class="calf_joint" />
            <geom
                            type="mesh"
                            rgba="0.498039 0.498039 0.498039 1"
                            mesh="FL_calf"
                            class="visual"
                        />
            <geom
                            size="0.012 0.007644 0.0242675"
                            pos="0.018049 0 -0.186508"
                            quat="0.998889 0 0.047125 0"
                            type="box"
                            class="collision"
                        />
            <geom
                            size="0.01 0.009 0.06"
                            pos="0.00376 0 -0.099894"
                            quat="0.994686 0 -0.102956 0"
                            type="box"
                            class="collision"
                        />
            <geom
                            size="0.014 0.007644 0.02"
                            pos="-0.005451 0 -0.017378"
                            quat="0.999978 0 0.00661145 0"
                            type="box"
                            class="collision"
                        />
            <geom
                            size="0.002 0.007644 0.02"
                            pos="-0.001309 0 -0.175631"
                            quat="0.981769 0 0.19008 0"
                            type="box"
                            class="collision"
                        />
            <geom
                            pos="0 0 -0.214"
                            quat="1 0 0 0"
                            type="mesh"
                            rgba="0.498039 0.498039 0.498039 1"
                            mesh="FL_foot"
                            class="visual"
                        />
            <body name="FL_foot" pos="0 0 -0.214">
              <geom class="foot" name="FL" />
            </body>
          </body>
        </body>
      </body>
      <body name="RR_hip" pos="-0.18453 -0.051 0">
        <inertial
                    pos="0.027882 0.015355 0"
                    quat="0.233155 0.682973 -0.137609 0.678417"
                    mass="0.079643"
                    diaginertia="8.72171e-05 7.7874e-05 2.29089e-05"
                />
        <joint name="RR_hip_joint" class="R_hip_joint" />
        <geom
                    type="mesh"
                    rgba="0.898039 0.917647 0.929412 1"
                    mesh="RR_hip"
                    class="visual"
                />
        <body name="RR_thigh" pos="0 -0.0975 0">
          <inertial
                        pos="-0.000498 0.038065 -0.024467"
                        quat="0.975282 -0.219111 0.024734 0.0142991"
                        mass="1.55038"
                        diaginertia="0.00679074 0.00586921 0.00204705"
                    />
          <joint name="RR_thigh_joint" class="R_thigh_joint" />
          <geom
                        type="mesh"
                        rgba="0.498039 0.498039 0.498039 1"
                        mesh="RR_thigh"
                        class="visual"
                    />
          <geom
                        size="0.0129095 0.013 0.06282"
                        pos="-0.029488 -0.000724 -0.10287"
                        quat="0.999071 0 -0.0430946 0"
                        type="box"
                        class="collision"
                    />
          <geom
                        size="0.00126 0.013 0.0627725"
                        pos="0.01289 -0.000372 -0.102949"
                        quat="0.997989 0 0.063395 0"
                        type="box"
                        class="collision"
                    />
          <geom
                        size="0.044 0.038455"
                        pos="0 0.02351 -0.000177"
                        quat="-0.707107 0.707107 0 0"
                        type="cylinder"
                        class="collision"
                    />
          <geom
                        size="0.015 0.002 0.02"
                        pos="-0.00614 0.014268 -0.188644"
                        quat="0.995396 0 -0.0958456 0"
                        type="box"
                        class="collision"
                    />
          <geom
                        size="0.015 0.002 0.02"
                        pos="-0.00614 -0.014448 -0.188644"
                        quat="0.995396 0 -0.0958456 0"
                        type="box"
                        class="collision"
                    />
          <body name="RR_calf" pos="0 0 -0.1985">
            <inertial
                            pos="0.00261631 0 -0.125302"
                            quat="0.706944 -0.0151852 -0.0151852 0.706944"
                            mass="0.183986"
                            diaginertia="0.00125035 0.0012368 3.55485e-05"
                        />
            <joint name="RR_calf_joint" class="calf_joint" />
            <geom
                            type="mesh"
                            rgba="0.498039 0.498039 0.498039 1"
                            mesh="RR_calf"
                            class="visual"
                        />
            <geom
                            size="0.012 0.007644 0.0242675"
                            pos="0.018049 0 -0.186508"
                            quat="0.998889 0 0.047125 0"
                            type="box"
                            class="collision"
                        />
            <geom
                            size="0.01 0.009 0.06"
                            pos="0.00376 0 -0.099894"
                            quat="0.994686 0 -0.102956 0"
                            type="box"
                            class="collision"
                        />
            <geom
                            size="0.014 0.007644 0.02"
                            pos="-0.005451 0 -0.017378"
                            quat="0.999978 0 0.00661145 0"
                            type="box"
                            class="collision"
                        />
            <geom
                            size="0.002 0.007644 0.02"
                            pos="-0.001309 0 -0.175631"
                            quat="0.981769 0 0.19008 0"
                            type="box"
                            class="collision"
                        />
            <geom
                            pos="0 0 -0.214"
                            quat="1 0 0 0"
                            type="mesh"
                            rgba="0.498039 0.498039 0.498039 1"
                            mesh="RR_foot"
                            class="visual"
                        />
            <body name="RR_foot" pos="0 0 -0.214">
              <geom class="foot" name="RR" />
            </body>
          </body>
        </body>
      </body>
      <body name="RL_hip" pos="-0.18453 0.051 0">
        <inertial
                    pos="0.027882 -0.015355 0"
                    quat="-0.233155 0.682973 0.137609 0.678417"
                    mass="0.079643"
                    diaginertia="8.72171e-05 7.7874e-05 2.29089e-05"
                />
        <joint name="RL_hip_joint" class="L_hip_joint" />
        <geom type="mesh" rgba="1 1 1 1" mesh="RL_hip" class="visual" />
        <body name="RL_thigh" pos="0 0.0975 0">
          <inertial
                        pos="-0.000498 -0.038065 -0.024467"
                        quat="0.975282 0.219111 0.024734 -0.0142991"
                        mass="1.55038"
                        diaginertia="0.00679074 0.00586921 0.00204705"
                    />
          <joint name="RL_thigh_joint" class="R_thigh_joint" />
          <geom
                        type="mesh"
                        rgba="0.498039 0.498039 0.498039 1"
                        mesh="RL_thigh"
                        class="visual"
                    />
          <geom
                        size="0.0129095 0.013 0.06282"
                        pos="-0.029488 0.000724 -0.10287"
                        quat="0.999071 0 -0.0430946 0"
                        type="box"
                        class="collision"
                    />
          <geom
                        size="0.00126 0.013 0.0627725"
                        pos="0.01289 0.000372 -0.102949"
                        quat="0.997989 0 0.063395 0"
                        type="box"
                        class="collision"
                    />
          <geom
                        size="0.044 0.038455"
                        pos="0 -0.02351 -0.000177"
                        quat="-0.707107 0.707107 0 0"
                        type="cylinder"
                        class="collision"
                    />
          <geom
                        size="0.015 0.002 0.02"
                        pos="-0.00614 -0.014268 -0.188644"
                        quat="0.995396 0 -0.0958456 0"
                        type="box"
                        class="collision"
                    />
          <geom
                        size="0.015 0.002 0.02"
                        pos="-0.00614 0.014448 -0.188644"
                        quat="0.995396 0 -0.0958456 0"
                        type="box"
                        class="collision"
                    />
          <body name="RL_calf" pos="0 0 -0.1985">
            <inertial
                            pos="0.00261631 0 -0.125302"
                            quat="0.706944 -0.0151852 -0.0151852 0.706944"
                            mass="0.183986"
                            diaginertia="0.00125035 0.0012368 3.55485e-05"
                        />
            <joint name="RL_calf_joint" class="calf_joint" />
            <geom
                            type="mesh"
                            rgba="0.498039 0.498039 0.498039 1"
                            mesh="RL_calf"
                            class="visual"
                        />
            <geom
                            size="0.012 0.007644 0.0242675"
                            pos="0.018049 0 -0.186508"
                            quat="0.998889 0 0.047125 0"
                            type="box"
                            class="collision"
                        />
            <geom
                            size="0.01 0.009 0.06"
                            pos="0.00376 0 -0.099894"
                            quat="0.994686 0 -0.102956 0"
                            type="box"
                            class="collision"
                        />
            <geom
                            size="0.014 0.007644 0.02"
                            pos="-0.005451 0 -0.017378"
                            quat="0.999978 0 0.00661145 0"
                            type="box"
                            class="collision"
                        />
            <geom
                            size="0.002 0.007644 0.02"
                            pos="-0.001309 0 -0.175631"
                            quat="0.981769 0 0.19008 0"
                            type="box"
                            class="collision"
                        />
            <geom
                            pos="0 0 -0.214"
                            quat="1 0 0 0"
                            type="mesh"
                            rgba="0.498039 0.498039 0.498039 1"
                            mesh="RL_foot"
                            class="visual"
                        />
            <body name="RL_foot" pos="0 0 -0.214">
              <geom class="foot" name="RL" />
            </body>
          </body>
        </body>
      </body>
    </body>
    
    <!-- 当前朝向箭头（绿色）- 使用freejoint控制位置，不影响物理 -->
    <body name="robot_heading_arrow" pos="0 0 0.66">
      <freejoint/>
      <geom name="robot_arrow_shaft" type="cylinder" size="0.04 0.1" 
            pos="0.15 0 0" quat="0.707107 0 0.707107 0" 
            rgba="0 1 0 0.8" contype="0" conaffinity="0"/>
      <geom name="robot_arrow_head" type="mesh" mesh="arrow_cone" 
            pos="0.23 -0.3 0.09" quat="0.707107 0 0.707107 0"
            rgba="0 1 0 0.8" contype="0" conaffinity="0"/>
    </body>
    
    <!-- 期望朝向箭头（蓝色）- 使用freejoint控制位置，不影响物理 -->
    <body name="desired_heading_arrow" pos="0 0 0.66">
      <freejoint/>
      <geom name="desired_arrow_shaft" type="cylinder" size="0.04 0.1" 
            pos="0.15 0 0" quat="0.707107 0 0.707107 0" 
            rgba="0 0 1 0.8" contype="0" conaffinity="0"/>
      <geom name="desired_arrow_head" type="mesh" mesh="arrow_cone" 
            pos="0.23 -0.3 0.09" quat="0.707107 0 0.707107 0"
            rgba="0 0 1 0.8" contype="0" conaffinity="0"/>
    </body>
  </worldbody>
  <actuator>
    <!-- FR - 前右 -->
    <motor class="vita" name="FR_hip_joint" joint="FR_hip_joint" />
    <motor class="vita" name="FR_thigh_joint" joint="FR_thigh_joint" />
    <motor class="calf_joint" name="FR_calf_joint" joint="FR_calf_joint" />
    <!-- FL - 前左 -->
    <motor class="vita" name="FL_hip_joint" joint="FL_hip_joint" />
    <motor class="vita" name="FL_thigh_joint" joint="FL_thigh_joint" />
    <motor class="calf_joint" name="FL_calf_joint" joint="FL_calf_joint" />
    <!-- RR - 后右 -->
    <motor class="vita" name="RR_hip_joint" joint="RR_hip_joint" />
    <motor class="vita" name="RR_thigh_joint" joint="RR_thigh_joint" />
    <motor class="calf_joint" name="RR_calf_joint" joint="RR_calf_joint" />
    <!-- RL - 后左 -->
    <motor class="vita" name="RL_hip_joint" joint="RL_hip_joint" />
    <motor class="vita" name="RL_thigh_joint" joint="RL_thigh_joint" />
    <motor class="calf_joint" name="RL_calf_joint" joint="RL_calf_joint" />
  </actuator>
  <sensor>
    <!-- 关节位置传感器 - 按照与执行器相同的顺序排列 -->
    <!-- FR - 前右 -->
    <jointpos name="FR_hip_joint_pos" joint="FR_hip_joint" />
    <jointpos name="FR_thigh_joint_pos" joint="FR_thigh_joint" />
    <jointpos name="FR_calf_joint_pos" joint="FR_calf_joint" />
    <!-- FL - 前左 -->
    <jointpos name="FL_hip_joint_pos" joint="FL_hip_joint" />
    <jointpos name="FL_thigh_joint_pos" joint="FL_thigh_joint" />
    <jointpos name="FL_calf_joint_pos" joint="FL_calf_joint" />
    <!-- RR - 后右 -->
    <jointpos name="RR_hip_joint_pos" joint="RR_hip_joint" />
    <jointpos name="RR_thigh_joint_pos" joint="RR_thigh_joint" />
    <jointpos name="RR_calf_joint_pos" joint="RR_calf_joint" />
    <!-- RL - 后左 -->
    <jointpos name="RL_hip_joint_pos" joint="RL_hip_joint" />
    <jointpos name="RL_thigh_joint_pos" joint="RL_thigh_joint" />
    <jointpos name="RL_calf_joint_pos" joint="RL_calf_joint" />
    <!-- 关节速度传感器 - 按照与执行器相同的顺序排列 -->
    <!-- FR - 前右 -->
    <jointvel name="FR_hip_joint_vel" joint="FR_hip_joint" />
    <jointvel name="FR_thigh_joint_vel" joint="FR_thigh_joint" />
    <jointvel name="FR_calf_joint_vel" joint="FR_calf_joint" />
    <!-- FL - 前左 -->
    <jointvel name="FL_hip_joint_vel" joint="FL_hip_joint" />
    <jointvel name="FL_thigh_joint_vel" joint="FL_thigh_joint" />
    <jointvel name="FL_calf_joint_vel" joint="FL_calf_joint" />
    <!-- RR - 后右 -->
    <jointvel name="RR_hip_joint_vel" joint="RR_hip_joint" />
    <jointvel name="RR_thigh_joint_vel" joint="RR_thigh_joint" />
    <jointvel name="RR_calf_joint_vel" joint="RR_calf_joint" />
    <!-- RL - 后左 -->
    <jointvel name="RL_hip_joint_vel" joint="RL_hip_joint" />
    <jointvel name="RL_thigh_joint_vel" joint="RL_thigh_joint" />
    <jointvel name="RL_calf_joint_vel" joint="RL_calf_joint" />
    <!-- 关节力矩传感器 - 按照与执行器相同的顺序排列 -->
    <!-- FR - 前右 -->
    <jointactuatorfrc
            name="FR_hip_joint_torque"
            joint="FR_hip_joint"
            noise="0.01"
        />
    <jointactuatorfrc
            name="FR_thigh_joint_torque"
            joint="FR_thigh_joint"
            noise="0.01"
        />
    <jointactuatorfrc
            name="FR_calf_joint_torque"
            joint="FR_calf_joint"
            noise="0.01"
        />
    <!-- FL - 前左 -->
    <jointactuatorfrc
            name="FL_hip_joint_torque"
            joint="FL_hip_joint"
            noise="0.01"
        />
    <jointactuatorfrc
            name="FL_thigh_joint_torque"
            joint="FL_thigh_joint"
            noise="0.01"
        />
    <jointactuatorfrc
            name="FL_calf_joint_torque"
            joint="FL_calf_joint"
            noise="0.01"
        />
    <!-- RR - 后右 -->
    <jointactuatorfrc
            name="RR_hip_joint_torque"
            joint="RR_hip_joint"
            noise="0.01"
        />
    <jointactuatorfrc
            name="RR_thigh_joint_torque"
            joint="RR_thigh_joint"
            noise="0.01"
        />
    <jointactuatorfrc
            name="RR_calf_joint_torque"
            joint="RR_calf_joint"
            noise="0.01"
        />
    <!-- RL - 后左 -->
    <jointactuatorfrc
            name="RL_hip_joint_torque"
            joint="RL_hip_joint"
            noise="0.01"
        />
    <jointactuatorfrc
            name="RL_thigh_joint_torque"
            joint="RL_thigh_joint"
            noise="0.01"
        />
    <jointactuatorfrc
            name="RL_calf_joint_torque"
            joint="RL_calf_joint"
            noise="0.01"
        />
    <!-- IMU传感器 -->
    <framequat name="trunk_quat" objtype="site" objname="trunk_imu" />
    <gyro name="base_gyro" site="trunk_imu" />
    <accelerometer name="trunk_acc" site="trunk_imu" />
    <!-- 位置和速度传感器 -->
    <framepos name="trunk_pos" objtype="site" objname="trunk_imu" />
    <framelinvel name="base_linvel" objtype="site" objname="trunk_imu" />
  </sensor>
</mujoco>
